<?xml version="1.0"?>

<robot name="orendes_85_gripper" xmlns:xacro="http://ros.org/wiki/xacro">
    <xacro:property name="pi" value="3.14159"/>
    
    <xacro:macro name="orendes_85_gripper" params="prefix parent *origin">

        <joint name="${prefix}orendes_85_base_joint" type="fixed">
            <parent link="${parent}"/>
            <child link="${prefix}orendes_85_base_link"/>
            <xacro:insert_block name="origin"/>
        </joint>

        <link name="${prefix}orendes_85_base_link">
            <visual>
                <geometry>
                    <mesh filename="package://orendes_gripper/meshes/visual/orendes_85_base_link.dae" scale="0.001 0.001 0.001"/>
                </geometry>
            </visual>
            <collision>
                <geometry>
                    <mesh filename="package://orendes_gripper/meshes/collision/orendes_85_base_link.stl" scale="0.001 0.001 0.001"/>
                </geometry>
            </collision>
            <inertial>
                <mass value="0.636951" />
                <origin xyz="0.0 0.0 0.0" />
                <inertia ixx="0.000380" ixy="0.000000" ixz="0.000000"
                         iyx="0.000000" iyy="0.001110" iyz="0.000000"
                         izx="0.000000" izy="0.000000" izz="0.001171" />
            </inertial>
        </link>

        <joint name="${prefix}orendes_85_left_finger_tip_joint" type="continuous">
            <parent link="${prefix}orendes_85_base_link"/>
            <child link="${prefix}orendes_85_left_finger_tip_link"/>
            <axis xyz="0 0 1"/>
            <origin rpy="0.0 0.0 0.0" xyz="-0.0199 0.008 0.045"/>
            <limit lower="-3.14" upper="3.14" velocity="100.0" effort="0.1"/>
        </joint>

        <joint name="${prefix}orendes_85_right_finger_tip_joint" type="continuous">
            <parent link="${prefix}orendes_85_base_link"/>
            <child link="${prefix}orendes_85_right_finger_tip_link"/>
            <axis xyz="0 0 1"/>
            <origin rpy="0.0 0.0 0.0" xyz="0.2545451627 -0.03180114443 0.0629"/>
            <limit lower="-3.14" upper="3.14" velocity="100.0" effort="0.1"/>
            <mimic joint="${prefix}orendes_85_left_finger_tip_joint" multiplier="-1"/>
        </joint>

        <link name="${prefix}orendes_85_left_finger_tip_link">
            <visual>
                <geometry>
                    <mesh filename="package://orendes_gripper/meshes/visual/orendes_85_left_finger_tip_link.dae" scale="0.001 0.001 0.001"/>
                </geometry>
            </visual>
            <collision>
                <geometry>
                    <mesh filename="package://orendes_gripper/meshes/collision/orendes_85_left_finger_tip_link.stl" scale="0.001 0.001 0.001"/>
                </geometry>
            </collision>
            <inertial>
                <mass value="0.018491" />
                <origin xyz="0.0 0.0 0.0" />
                <inertia ixx="0.000009" ixy="-0.000001" ixz="0.000000"
                         iyx="-0.000001" iyy="0.000001" iyz="0.000000"
                         izx="0.000000" izy="0.000000" izz="0.000010" />
            </inertial>
        </link> 
        
        <link name="${prefix}orendes_85_right_finger_tip_link">
            <visual>
                <geometry>
                    <mesh filename="package://orendes_gripper/meshes/visual/orendes_85_right_finger_tip_link.dae" scale="0.001 0.001 0.001"/>
                </geometry>
            </visual>
            <collision>
                <geometry>
                    <mesh filename="package://orendes_gripper/meshes/collision/orendes_85_right_finger_tip_link.stl" scale="0.001 0.001 0.001"/>
                </geometry>
            </collision>
            <inertial>
                <mass value="0.018491" />
                <origin xyz="0.0 0.0 0.0" />
                <inertia ixx="0.000009" ixy="-0.000001" ixz="0.000000"
                         iyx="-0.000001" iyy="0.000001" iyz="0.000000"
                         izx="0.000000" izy="0.000000" izz="0.000010" />
            </inertial>
        </link>
    </xacro:macro>
</robot>
